<?xml version="1.0" encoding="utf-8"?>
<!-- =================================================================================== -->
<!-- |    This document was autogenerated by xacro from motomini.xacro                 | -->
<!-- |    EDITING THIS FILE BY HAND IS NOT RECOMMENDED                                 | -->
<!-- =================================================================================== -->
<robot name="motoman_motomini">
  <!-- Properties -->
  <material name="yaskawa_blue">
    <color rgba="0.12941 0.14902 0.74902 1"/>
  </material>
  <!-- World frame -->
  <link name="world"/>
  <!-- Adding table to the world -->
  <link name="table">
    <origin rpy="0 0 0" xyz="0.0 0.0 0"/>
    <inertial>
      <mass value="5"/>
      <origin xyz="0 0 0"/>
      <inertia ixx="1" ixy="0.0" ixz="0.0" iyy="1" iyz="0.0" izz="1"/>
    </inertial>
    <visual>
      <geometry>
        <box size="0.83 0.830 0.001"/>
      </geometry>
      <material name="light_grey">
        <color rgba="0.7 0.7 0.7 1.0"/>
      </material>
    </visual>
    <collision>
      <geometry>
        <box size="0.83 0.830 0.001"/>
      </geometry>
    </collision>
  </link>
  <!-- link list -->
  <link name="base_link">
    <visual>
      <geometry>
        <mesh filename="package://motoman_motomini_support/meshes/motomini/visual/base_link.stl"/>
      </geometry>
      <material name="yaskawa_blue"/>
    </visual>
    <collision>
      <geometry>
        <mesh filename="package://motoman_motomini_support/meshes/motomini/collision/base_link.stl"/>
      </geometry>
    </collision>
  </link>
  <link name="link_1_s">
    <visual>
      <geometry>
        <mesh filename="package://motoman_motomini_support/meshes/motomini/visual/link_1_s.stl"/>
      </geometry>
      <material name="yaskawa_blue"/>
    </visual>
    <collision>
      <geometry>
        <mesh filename="package://motoman_motomini_support/meshes/motomini/collision/link_1_s.stl"/>
      </geometry>
    </collision>
  </link>
  <link name="link_2_l">
    <visual>
      <geometry>
        <mesh filename="package://motoman_motomini_support/meshes/motomini/visual/link_2_l.stl"/>
      </geometry>
      <material name="yaskawa_blue"/>
    </visual>
    <collision>
      <geometry>
        <mesh filename="package://motoman_motomini_support/meshes/motomini/collision/link_2_l.stl"/>
      </geometry>
    </collision>
  </link>
  <link name="link_3_u">
    <visual>
      <geometry>
        <mesh filename="package://motoman_motomini_support/meshes/motomini/visual/link_3_u.stl"/>
      </geometry>
      <material name="yaskawa_blue"/>
    </visual>
    <collision>
      <geometry>
        <mesh filename="package://motoman_motomini_support/meshes/motomini/collision/link_3_u.stl"/>
      </geometry>
    </collision>
  </link>
  <link name="link_4_r">
    <visual>
      <geometry>
        <mesh filename="package://motoman_motomini_support/meshes/motomini/visual/link_4_r.stl"/>
      </geometry>
      <material name="yaskawa_blue"/>
    </visual>
    <collision>
      <geometry>
        <mesh filename="package://motoman_motomini_support/meshes/motomini/collision/link_4_r.stl"/>
      </geometry>
    </collision>
  </link>
  <link name="link_5_b">
    <visual>
      <geometry>
        <mesh filename="package://motoman_motomini_support/meshes/motomini/visual/link_5_b.stl"/>
      </geometry>
      <material name="yaskawa_blue"/>
    </visual>
    <collision>
      <geometry>
        <mesh filename="package://motoman_motomini_support/meshes/motomini/collision/link_5_b.stl"/>
      </geometry>
    </collision>
  </link>
  <link name="link_6_t">
    <visual>
      <geometry>
        <mesh filename="package://motoman_motomini_support/meshes/motomini/visual/link_6_t.stl"/>
      </geometry>
      <material name="yaskawa_blue"/>
    </visual>
    <collision>
      <geometry>
        <mesh filename="package://motoman_motomini_support/meshes/motomini/collision/link_6_t.stl"/>
      </geometry>
    </collision>
  </link>
  <link name="tool0"/>
  <!-- end of link list -->
  <!-- Kinect link -->
  <material name="black">
    <color rgba="0. 0. 0. 1"/>
  </material>
  <material name="dark_grey">
    <color rgba="0.1 0.1 0.1 1"/>
  </material>
  <material name="grey">
    <color rgba="0.6 0.6 0.6 1"/>
  </material>
  <material name="white">
    <color rgba="0.9 0.9 0.9 1"/>
  </material>
  <link name="camera_link">
    <visual>
      <origin rpy="0 0 0" xyz="0 0 0"/>
      <geometry>
        <box size="0.05 0.2 0.05"/>
      </geometry>
      <material name="light_grey">
        <color rgba="0.7 0.7 0.7 1.0"/>
      </material>
    </visual>
    <collision>
      <origin rpy="0 0 0" xyz="0 0 0"/>
      <geometry>
        <box size="0.05 0.2 0.05"/>
      </geometry>
    </collision>
  </link>
  <!--link name="kinect2_rgb_optical_frame" >
</link-->
  <joint name="camera_joint" type="fixed">
    <parent link="base_link"/>
    <child link="camera_link"/>
    <origin rpy="0 0.4712 -3.14159265359" xyz="1.17 0 0.48"/>
  </joint>
  <!--0.865joint name="camera_optical_joint" type="fixed">  0.4712 ${{-M_PI/2}-0.4712}
    <origin xyz="0 0 0" rpy="${-M_PI/2} 0 ${-M_PI/2}" />
    <parent link="kinect2_link" />
    <child link="kinect2_rgb_optical_frame" />
</joint-->
  <!-- joint list -->
  <joint name="world_joint" type="fixed">
    <parent link="world"/>
    <child link="table"/>
    <origin rpy="0.0 0.0 -1.57" xyz="0.0 0.0 0"/>
  </joint>
  <joint name="table_joint" type="fixed">
    <parent link="table"/>
    <child link="base_link"/>
    <origin rpy="0.0 0.0 1.57079632679" xyz="0 -0.1015 0.0"/>
  </joint>
  <joint name="joint_1_s" type="revolute">
    <parent link="base_link"/>
    <child link="link_1_s"/>
    <origin rpy="0 0 0" xyz="0 0 0.103"/>
    <axis xyz="0 0 1"/>
    <limit effort="0.12" lower="-2.9670" upper="2.9670" velocity="5.4977"/>
  </joint>
  <joint name="joint_2_l" type="revolute">
    <parent link="link_1_s"/>
    <child link="link_2_l"/>
    <origin rpy="0 0 0" xyz="0.020 0 0"/>
    <axis xyz="0 1 0"/>
    <limit effort="0.12" lower="-1.4835" upper="1.5707" velocity="5.4977"/>
  </joint>
  <joint name="joint_3_u" type="revolute">
    <parent link="link_2_l"/>
    <child link="link_3_u"/>
    <origin rpy="0 0 0" xyz="0 0 0.165"/>
    <axis xyz="0 -1 0"/>
    <limit effort="0.12" lower="-0.8726" upper="1.5707" velocity="7.3304"/>
  </joint>
  <joint name="joint_4_r" type="revolute">
    <parent link="link_3_u"/>
    <child link="link_4_r"/>
    <origin rpy="0 0 0" xyz="0.165 0 0"/>
    <axis xyz="-1 0 0"/>
    <limit effort="0.07" lower="-2.4434" upper="2.4434" velocity="10.4719"/>
  </joint>
  <joint name="joint_5_b" type="revolute">
    <parent link="link_4_r"/>
    <child link="link_5_b"/>
    <origin rpy="0 0 0" xyz="0 0 0"/>
    <axis xyz="0 -1 0"/>
    <limit effort="0.07" lower="-0.5235" upper="3.6651" velocity="10.4719"/>
  </joint>
  <joint name="joint_6_t" type="revolute">
    <parent link="link_5_b"/>
    <child link="link_6_t"/>
    <origin rpy="0 0 0" xyz="0 0 0"/>
    <axis xyz="0 0 1"/>
    <limit effort="0.07" lower="-6.2831" upper="6.2831" velocity="10.4719"/>
  </joint>
  <joint name="joint_6_t-tool0" type="fixed">
    <origin rpy="3.14159265359 0 0" xyz="0 0 -0.040 "/>
    <parent link="link_6_t"/>
    <child link="tool0"/>
  </joint>
  <!-- end of joint list -->
  <!-- ROS base_link to Robot Manufacturer World Coordinates transform -->
  <link name="base"/>
  <joint name="base_link-base" type="fixed">
    <origin rpy="0 0 0" xyz="0 0 0.103"/>
    <parent link="base_link"/>
    <child link="base"/>
  </joint>
  <link name="gripper_base">
    <visual>
      <geometry>
        <mesh filename="package://motoman_motomini_support/meshes/gripper/base.stl"/>
      </geometry>
      <material name="white"/>
    </visual>
    <collision>
      <geometry>
        <mesh filename="package://motoman_motomini_support/meshes/gripper/base.stl"/>
      </geometry>
    </collision>
  </link>
  <link name="claw_1a">
    <visual>
      <geometry>
        <mesh filename="package://motoman_motomini_support/meshes/gripper/claw_1.stl"/>
      </geometry>
      <material name="white"/>
    </visual>
    <collision>
      <geometry>
        <mesh filename="package://motoman_motomini_support/meshes/gripper/claw_1.stl"/>
      </geometry>
    </collision>
  </link>
  <link name="claw_1b">
    <visual>
      <geometry>
        <mesh filename="package://motoman_motomini_support/meshes/gripper/claw_1.stl"/>
      </geometry>
      <material name="white"/>
    </visual>
    <collision>
      <geometry>
        <mesh filename="package://motoman_motomini_support/meshes/gripper/claw_1.stl"/>
      </geometry>
    </collision>
  </link>
  <link name="claw_2a">
    <visual>
      <geometry>
        <mesh filename="package://motoman_motomini_support/meshes/gripper/claw_2.stl"/>
      </geometry>
      <material name="white"/>
    </visual>
    <collision>
      <geometry>
        <mesh filename="package://motoman_motomini_support/meshes/gripper/claw_2.stl"/>
      </geometry>
    </collision>
  </link>
  <link name="claw_2b">
    <visual>
      <geometry>
        <mesh filename="package://motoman_motomini_support/meshes/gripper/claw_2.stl"/>
      </geometry>
      <material name="white"/>
    </visual>
    <collision>
      <geometry>
        <mesh filename="package://motoman_motomini_support/meshes/gripper/claw_2.stl"/>
      </geometry>
    </collision>
  </link>
  <link name="link_1a">
    <visual>
      <geometry>
        <mesh filename="package://motoman_motomini_support/meshes/gripper/link_1.stl"/>
      </geometry>
      <material name="white"/>
    </visual>
    <collision>
      <geometry>
        <mesh filename="package://motoman_motomini_support/meshes/gripper/link_1.stl"/>
      </geometry>
    </collision>
  </link>
  <link name="link_1b">
    <visual>
      <geometry>
        <mesh filename="package://motoman_motomini_support/meshes/gripper/link_1.stl"/>
      </geometry>
      <material name="white"/>
    </visual>
    <collision>
      <geometry>
        <mesh filename="package://motoman_motomini_support/meshes/gripper/link_1.stl"/>
      </geometry>
    </collision>
  </link>
  <link name="link_2a">
    <visual>
      <geometry>
        <mesh filename="package://motoman_motomini_support/meshes/gripper/link_2.stl"/>
      </geometry>
      <material name="white"/>
    </visual>
    <collision>
      <geometry>
        <mesh filename="package://motoman_motomini_support/meshes/gripper/link_2.stl"/>
      </geometry>
    </collision>
  </link>
  <link name="link_2b">
    <visual>
      <geometry>
        <mesh filename="package://motoman_motomini_support/meshes/gripper/link_2.stl"/>
      </geometry>
      <material name="white"/>
    </visual>
    <collision>
      <geometry>
        <mesh filename="package://motoman_motomini_support/meshes/gripper/link_2.stl"/>
      </geometry>
    </collision>
  </link>
  <link name="link_2c">
    <visual>
      <geometry>
        <mesh filename="package://motoman_motomini_support/meshes/gripper/link_2.stl"/>
      </geometry>
      <material name="white"/>
    </visual>
    <collision>
      <geometry>
        <mesh filename="package://motoman_motomini_support/meshes/gripper/link_2.stl"/>
      </geometry>
    </collision>
  </link>
  <link name="link_2d">
    <visual>
      <geometry>
        <mesh filename="package://motoman_motomini_support/meshes/gripper/link_2.stl"/>
      </geometry>
      <material name="white"/>
    </visual>
    <collision>
      <geometry>
        <mesh filename="package://motoman_motomini_support/meshes/gripper/link_2.stl"/>
      </geometry>
    </collision>
  </link>
  <joint name="gripper_joint" type="fixed">
    <parent link="tool0"/>
    <child link="gripper_base"/>
    <origin rpy="0 -1.5707 3.142" xyz="0 0 0"/>
    <!--<limit lower= "-3.0" upper= "3.0" effort="200" velocity="3" />
    <axis xyz = "0 0 1" />-->
  </joint>
  <joint name="claw_1b_joint" type="revolute">
    <parent link="gripper_base"/>
    <child link="claw_1b"/>
    <limit effort="200" lower="-3.0" upper="3.0" velocity="3"/>
    <axis xyz="0 0 1"/>
    <origin rpy="0.0 0.0 0" xyz="0.045 0.01154 0.017503"/>
  </joint>
  <joint name="claw_1a_joint" type="revolute">
    <parent link="gripper_base"/>
    <child link="claw_1a"/>
    <limit effort="200" lower="-3.0" upper="3.0" velocity="3"/>
    <axis xyz="0 0 1"/>
    <origin rpy="0.0 0.0 0" xyz="0.045 -0.01154 0.017503"/>
    <mimic joint="claw_1b_joint" multiplier="-1"/>
  </joint>
  <joint name="claw_2a_joint" type="revolute">
    <parent link="claw_1a"/>
    <child link="claw_2a"/>
    <limit effort="200" lower="-3.0" upper="3.0" velocity="3"/>
    <axis xyz="0 0 1"/>
    <!--origin rpy="0.0 3.142 0" xyz="0.032 -0.011563 0.0050405"/-->
    <origin rpy="0.0 3.142 0.2" xyz="0.03 0 -0.005"/>
    <mimic joint="claw_1b_joint" multiplier="-1"/>
  </joint>
  <joint name="claw_2b_joint" type="revolute">
    <parent link="claw_1b"/>
    <child link="claw_2b"/>
    <limit effort="200" lower="-3.0" upper="3.0" velocity="3"/>
    <axis xyz="0 0 1"/>
    <origin rpy="3.142 3.142 -0.2" xyz="0.03 0 -0.005"/>
    <mimic joint="claw_1b_joint" multiplier="-1"/>
  </joint>
  <joint name="link_1a_joint" type="revolute">
    <parent link="gripper_base"/>
    <child link="link_1a"/>
    <limit effort="200" lower="-3.0" upper="3.0" velocity="3"/>
    <axis xyz="0 0 1"/>
    <origin rpy="0.0 0.0 3.142" xyz="0.045 -0.01154 0.0044"/>
    <mimic joint="claw_1b_joint" multiplier="-1"/>
  </joint>
  <joint name="link_1b_joint" type="revolute">
    <parent link="gripper_base"/>
    <child link="link_1b"/>
    <limit effort="200" lower="-3.0" upper="3.0" velocity="3"/>
    <axis xyz="0 0 1"/>
    <origin rpy="0.0 0.0 3.142" xyz="0.045 0.01154 0.0044"/>
    <mimic joint="claw_1b_joint" multiplier="1"/>
  </joint>
  <joint name="link_2a_joint" type="revolute">
    <parent link="gripper_base"/>
    <child link="link_2a"/>
    <limit effort="200" lower="-3.0" upper="3.0" velocity="3"/>
    <axis xyz="0 0 1"/>
    <origin rpy="0.0 0.0 3.142" xyz="0.062257 -0.0040985 0.02"/>
    <mimic joint="claw_1b_joint" multiplier="-1"/>
  </joint>
  <joint name="link_2b_joint" type="revolute">
    <parent link="gripper_base"/>
    <child link="link_2b"/>
    <limit effort="200" lower="-3.0" upper="3.0" velocity="3"/>
    <axis xyz="0 0 1"/>
    <origin rpy="0.0 0.0 3.142" xyz="0.062257 0.0040985 0.02"/>
    <mimic joint="claw_1b_joint" multiplier="1"/>
  </joint>
  <joint name="link_2c_joint" type="revolute">
    <parent link="gripper_base"/>
    <child link="link_2c"/>
    <limit effort="200" lower="-3.0" upper="3.0" velocity="3"/>
    <axis xyz="0 0 1"/>
    <origin rpy="0.0 0.0 3.142" xyz="0.062257 -0.0040985 0.005"/>
    <mimic joint="claw_1b_joint" multiplier="-1"/>
  </joint>
  <joint name="link_2d_joint" type="revolute">
    <parent link="gripper_base"/>
    <child link="link_2d"/>
    <limit effort="200" lower="-3.0" upper="3.0" velocity="3"/>
    <axis xyz="0 0 1"/>
    <origin rpy="0.0 0.0 3.142" xyz="0.062257 0.0040985 0.005"/>
    <mimic joint="claw_1b_joint" multiplier="1"/>
  </joint>
  <link name="realsense_link">
    <collision>
      <origin rpy="0 0 0" xyz="0.02 0 0"/>
      <geometry>
        <box size="0.001 0.001 0.001"/>
      </geometry>
    </collision>
    <visual>
      <origin rpy="1.5707 0 1.5707" xyz="0 0 0"/>
      <geometry>
        <mesh filename="package://motoman_motomini_support/meshes/NAVRS.STL"/>
      </geometry>
    </visual>
    <inertial>
      <mass value="1e-5"/>
      <origin rpy="0 0 0" xyz="0 0 0"/>
      <inertia ixx="0" ixy="0" ixz="0" iyy="0" iyz="0" izz="0"/>
    </inertial>
  </link>
  <joint name="realsense_joint" type="fixed">
    <parent link="gripper_base"/>
    <child link="realsense_link"/>
    <origin rpy="0 0 0" xyz="0.05 0 0.055"/>
    <!--<limit lower= "-3.0" upper= "3.0" effort="200" velocity="3" />
    <axis xyz = "0 0 1" />-->
  </joint>
  <!--joint name="camera_optical_joint2" type="fixed">
    <origin xyz="0 0 0" rpy="${-pi/2} 0 ${-pi/2}"/>
    <parent link="camera_link2"/>
    <child link="camera_rgb_frame2"/>
  </joint>

  <link name="camera_rgb_frame2">
  </link>

  <joint name="camera_depth_joint2" type="fixed">
    <origin xyz="0 0 0" rpy="${-pi/2} 0 ${-pi/2}"/>
    <parent link="camera_link2"/>
    <child link="camera_depth_frame2"/>
  </joint>

    <link name="camera_depth_frame2">
  </link-->
</robot>
