<?xml version="1.0" encoding="utf-8"?>
<!-- =================================================================================== -->
<!-- |    This document was autogenerated by xacro from motomini.xacro                 | -->
<!-- |    EDITING THIS FILE BY HAND IS NOT RECOMMENDED                                 | -->
<!-- =================================================================================== -->
<robot name="motoman_motomini">
  <!-- World frame -->
  <link name="world"/>
  <link name="table">
    <origin rpy="0 0 0" xyz="0.0 0.0 0"/>
    <inertial>
      <mass value="5"/>
      <origin xyz="0 0 0"/>
      <inertia ixx="1" ixy="0.0" ixz="0.0" iyy="1" iyz="0.0" izz="1"/>
    </inertial>
    <visual>
      <geometry>
        <box size="0.83 0.830 0.001"/>
      </geometry>
      <material name="light_grey">
        <color rgba="0.7 0.7 0.7 1.0"/>
      </material>
    </visual>
    <collision>
      <geometry>
        <box size="0.83 0.830 0.001"/>
      </geometry>
    </collision>
  </link>
  <link name="leg1">
    <origin rpy="0 0 0" xyz="0.0 0.0 0"/>
    <inertial>
      <mass value="1"/>
      <origin xyz="0 0 0"/>
      <inertia ixx="1" ixy="0.0" ixz="0.0" iyy="1" iyz="0.0" izz="1"/>
    </inertial>
    <visual>
      <geometry>
        <box size="0.03 0.03 0.7"/>
      </geometry>
      <material name="light_grey">
        <color rgba="0.7 0.7 0.7 1.0"/>
      </material>
    </visual>
    <collision>
      <geometry>
        <box size="0.03 0.03 0.7"/>
      </geometry>
    </collision>
  </link>
  <link name="leg2">
    <origin rpy="0 0 0" xyz="0.0 0.0 0"/>
    <inertial>
      <mass value="1"/>
      <origin xyz="0 0 0"/>
      <inertia ixx="1" ixy="0.0" ixz="0.0" iyy="1" iyz="0.0" izz="1"/>
    </inertial>
    <visual>
      <geometry>
        <box size="0.03 0.03 0.7"/>
      </geometry>
      <material name="light_grey">
        <color rgba="0.7 0.7 0.7 1.0"/>
      </material>
    </visual>
    <collision>
      <geometry>
        <box size="0.03 0.03 0.7"/>
      </geometry>
    </collision>
  </link>
  <link name="leg3">
    <origin rpy="0 0 0" xyz="0.0 0.0 0"/>
    <inertial>
      <mass value="1"/>
      <origin xyz="0 0 0"/>
      <inertia ixx="1" ixy="0.0" ixz="0.0" iyy="1" iyz="0.0" izz="1"/>
    </inertial>
    <visual>
      <geometry>
        <box size="0.03 0.03 0.7"/>
      </geometry>
      <material name="light_grey">
        <color rgba="0.7 0.7 0.7 1.0"/>
      </material>
    </visual>
    <collision>
      <geometry>
        <box size="0.03 0.03 0.7"/>
      </geometry>
    </collision>
  </link>
  <link name="leg4">
    <origin rpy="0 0 0" xyz="0.0 0.0 0"/>
    <inertial>
      <mass value="1"/>
      <origin xyz="0 0 0"/>
      <inertia ixx="1" ixy="0.0" ixz="0.0" iyy="1" iyz="0.0" izz="1"/>
    </inertial>
    <visual>
      <geometry>
        <box size="0.03 0.03 0.7"/>
      </geometry>
      <material name="light_grey">
        <color rgba="0.7 0.7 0.7 1.0"/>
      </material>
    </visual>
    <collision>
      <geometry>
        <box size="0.03 0.03 0.7"/>
      </geometry>
    </collision>
  </link>
  <joint name="world_joint" type="fixed">
    <parent link="world"/>
    <child link="table"/>
    <origin rpy="0 0 -1.57079632679" xyz="0 0 0"/>
    <!--<limit lower= "-3.0" upper= "3.0" effort="200" velocity="3" />
    <axis xyz = "0 0 1" />-->
  </joint>
  <joint name="leg1_joint" type="fixed">
    <parent link="table"/>
    <child link="leg1"/>
    <origin rpy="0.0 0.0 0" xyz="0.4 0.4 -0.35"/>
  </joint>
  <joint name="leg2_joint" type="fixed">
    <parent link="table"/>
    <child link="leg2"/>
    <origin rpy="0 0 0" xyz="0.4 -0.4 -0.35"/>
  </joint>
  <joint name="leg3_joint" type="fixed">
    <parent link="table"/>
    <child link="leg3"/>
    <origin rpy="0 0 0" xyz="-0.4 0.4 -0.35"/>
  </joint>
  <joint name="leg4_joint" type="fixed">
    <parent link="table"/>
    <child link="leg4"/>
    <origin rpy="0 0 0" xyz="-0.4 -0.4 -0.35"/>
  </joint>
  <!-- Properties -->
  <material name="yaskawa_blue">
    <color rgba="0.12941 0.14902 0.74902 1"/>
  </material>
  <!-- link list -->
  <link name="base_link">
    <visual>
      <geometry>
        <mesh filename="package://motoman_motomini_support/meshes/motomini/visual/base_link.stl"/>
      </geometry>
      <material name="yaskawa_blue"/>
    </visual>
    <collision>
      <geometry>
        <mesh filename="package://motoman_motomini_support/meshes/motomini/collision/base_link.stl"/>
      </geometry>
    </collision>
    <inertial>
      <origin rpy="0 0 0" xyz="0 0 0"/>
      <mass value="0.1"/>
      <inertia ixx="0.001" ixy="0.001" ixz="0.001" iyy="0.001" iyz="0.001" izz="0.001"/>
    </inertial>
  </link>
  <link name="link_1_s">
    <visual>
      <geometry>
        <mesh filename="package://motoman_motomini_support/meshes/motomini/visual/link_1_s.stl"/>
      </geometry>
      <material name="yaskawa_blue"/>
    </visual>
    <collision>
      <geometry>
        <mesh filename="package://motoman_motomini_support/meshes/motomini/collision/link_1_s.stl"/>
      </geometry>
    </collision>
    <inertial>
      <origin rpy="0 0 0" xyz="0 0 0"/>
      <mass value="0.1"/>
      <inertia ixx="0.001" ixy="0.001" ixz="0.001" iyy="0.001" iyz="0.001" izz="0.001"/>
    </inertial>
  </link>
  <link name="link_2_l">
    <visual>
      <geometry>
        <mesh filename="package://motoman_motomini_support/meshes/motomini/visual/link_2_l.stl"/>
      </geometry>
      <material name="yaskawa_blue"/>
    </visual>
    <collision>
      <geometry>
        <mesh filename="package://motoman_motomini_support/meshes/motomini/collision/link_2_l.stl"/>
      </geometry>
    </collision>
    <inertial>
      <origin rpy="0 0 0" xyz="0 0 0"/>
      <mass value="0.1"/>
      <inertia ixx="0.001" ixy="0.001" ixz="0.001" iyy="0.001" iyz="0.001" izz="0.001"/>
    </inertial>
  </link>
  <link name="link_3_u">
    <visual>
      <geometry>
        <mesh filename="package://motoman_motomini_support/meshes/motomini/visual/link_3_u.stl"/>
      </geometry>
      <material name="yaskawa_blue"/>
    </visual>
    <collision>
      <geometry>
        <mesh filename="package://motoman_motomini_support/meshes/motomini/collision/link_3_u.stl"/>
      </geometry>
    </collision>
    <inertial>
      <origin rpy="0 0 0" xyz="0 0 0"/>
      <mass value="0.1"/>
      <inertia ixx="0.001" ixy="0.001" ixz="0.001" iyy="0.001" iyz="0.001" izz="0.001"/>
    </inertial>
  </link>
  <link name="link_4_r">
    <visual>
      <geometry>
        <mesh filename="package://motoman_motomini_support/meshes/motomini/visual/link_4_r.stl"/>
      </geometry>
      <material name="yaskawa_blue"/>
    </visual>
    <collision>
      <geometry>
        <mesh filename="package://motoman_motomini_support/meshes/motomini/collision/link_4_r.stl"/>
      </geometry>
    </collision>
    <inertial>
      <origin rpy="0 0 0" xyz="0 0 0"/>
      <mass value="0.1"/>
      <inertia ixx="0.001" ixy="0.001" ixz="0.001" iyy="0.001" iyz="0.001" izz="0.001"/>
    </inertial>
  </link>
  <link name="link_5_b">
    <visual>
      <geometry>
        <mesh filename="package://motoman_motomini_support/meshes/motomini/visual/link_5_b.stl"/>
      </geometry>
      <material name="yaskawa_blue"/>
    </visual>
    <collision>
      <geometry>
        <mesh filename="package://motoman_motomini_support/meshes/motomini/collision/link_5_b.stl"/>
      </geometry>
    </collision>
    <inertial>
      <origin rpy="0 0 0" xyz="0 0 0"/>
      <mass value="0.1"/>
      <inertia ixx="0.001" ixy="0.001" ixz="0.001" iyy="0.001" iyz="0.001" izz="0.001"/>
    </inertial>
  </link>
  <link name="link_6_t">
    <visual>
      <geometry>
        <mesh filename="package://motoman_motomini_support/meshes/motomini/visual/link_6_t.stl"/>
      </geometry>
      <material name="yaskawa_blue"/>
    </visual>
    <collision>
      <geometry>
        <mesh filename="package://motoman_motomini_support/meshes/motomini/collision/link_6_t.stl"/>
      </geometry>
    </collision>
    <inertial>
      <origin rpy="0 0 0" xyz="0 0 0"/>
      <mass value="0.1"/>
      <inertia ixx="0.001" ixy="0.001" ixz="0.001" iyy="0.001" iyz="0.001" izz="0.001"/>
    </inertial>
  </link>
  <link name="tool0"/>
  <link name="tool_tip"/>
  <!-- end of link list -->
  <!-- Kinect link -->
  <material name="black">
    <color rgba="0. 0. 0. 1"/>
  </material>
  <material name="dark_grey">
    <color rgba="0.1 0.1 0.1 1"/>
  </material>
  <material name="grey">
    <color rgba="0.6 0.6 0.6 1"/>
  </material>
  <material name="white">
    <color rgba="0.9 0.9 0.9 1"/>
  </material>
  <link name="camera_link">
    <visual>
      <origin rpy="0 0 0" xyz="0 0 0"/>
      <geometry>
        <box size="0.05 0.2 0.05"/>
      </geometry>
      <material name="light_grey">
        <color rgba="0.7 0.7 0.7 1.0"/>
      </material>
    </visual>
    <collision>
      <origin rpy="0 0 0" xyz="0 0 0"/>
      <geometry>
        <box size="0.05 0.2 0.05"/>
      </geometry>
    </collision>
  </link>
  <link name="camera_rgb_optical_frame"/>
  <joint name="camera_joint" type="fixed">
    <parent link="base_link"/>
    <child link="camera_link"/>
    <origin xyz="1.17 0.009 0.52" rpy="0.03 0.49 -3.14159265359"/>
  </joint>
  <joint name="camera_optical_joint" type="fixed">
    <!--0.4712 ${{-M_PI/2}-0.4712}-->
    <origin rpy="-1.57079632679 0 -1.57079632679" xyz="0 0 0"/>
    <parent link="camera_link"/>
    <child link="camera_rgb_optical_frame"/>
  </joint>
  <!-- joint list -->
  <!--joint name="world_joint" type="fixed">
    <parent link="world"/>
    <child link="table"/>
    <origin rpy="0.0 0.0 -1.57" xyz="0.0 0.0 0"/>
  </joint-->
  <joint name="table_joint" type="fixed">
    <parent link="table"/>
    <child link="base_link"/>
    <origin rpy="0.0 0.0 1.57079632679" xyz="0 -0.1015 0.0"/>
  </joint>
  <joint name="joint_1_s" type="revolute">
    <parent link="base_link"/>
    <child link="link_1_s"/>
    <origin rpy="0 0 0" xyz="0 0 0.103"/>
    <axis xyz="0 0 1"/>
    <limit effort="0.12" lower="-2.9670" upper="2.9670" velocity="5.4977"/>
  </joint>
  <joint name="joint_2_l" type="revolute">
    <parent link="link_1_s"/>
    <child link="link_2_l"/>
    <origin rpy="0 0 0" xyz="0.020 0 0"/>
    <axis xyz="0 1 0"/>
    <limit effort="0.12" lower="-1.4835" upper="1.5707" velocity="5.4977"/>
  </joint>
  <joint name="joint_3_u" type="revolute">
    <parent link="link_2_l"/>
    <child link="link_3_u"/>
    <origin rpy="0 0 0" xyz="0 0 0.165"/>
    <axis xyz="0 -1 0"/>
    <limit effort="0.12" lower="-0.8726" upper="1.5707" velocity="7.3304"/>
  </joint>
  <joint name="joint_4_r" type="revolute">
    <parent link="link_3_u"/>
    <child link="link_4_r"/>
    <origin rpy="0 0 0" xyz="0.165 0 0"/>
    <axis xyz="-1 0 0"/>
    <limit effort="0.07" lower="-2.4434" upper="2.4434" velocity="10.4719"/>
  </joint>
  <joint name="joint_5_b" type="revolute">
    <parent link="link_4_r"/>
    <child link="link_5_b"/>
    <origin rpy="0 0 0" xyz="0 0 0"/>
    <axis xyz="0 -1 0"/>
    <limit effort="0.07" lower="-0.5235" upper="3.6651" velocity="10.4719"/>
  </joint>
  <joint name="joint_6_t" type="revolute">
    <parent link="link_5_b"/>
    <child link="link_6_t"/>
    <origin rpy="0 0 0" xyz="0 0 0"/>
    <axis xyz="0 0 1"/>
    <limit effort="0.07" lower="-1.57079632679" upper="1.57079632679" velocity="10.4719"/>
  </joint>
  <joint name="joint_6_t-tool0" type="fixed">
    <origin rpy="3.14159265359 0 0" xyz="0 0 -0.040 "/>
    <parent link="link_6_t"/>
    <child link="tool0"/>
  </joint>
  <joint name="gripper_tip" type="fixed">
    <origin rpy="3.14159265359 -1.57079632679 0" xyz="0.012 0 0.115 "/>
    <parent link="tool0"/>
    <child link="tool_tip"/>
  </joint>
  <!-- end of joint list -->
  <!-- ROS base_link to Robot Manufacturer World Coordinates transform -->
  <link name="base"/>
  <joint name="base_link-base" type="fixed">
    <origin rpy="0 0 0" xyz="0 0 0.103"/>
    <parent link="base_link"/>
    <child link="base"/>
  </joint>
  <gazebo reference="joint_1_s">
    <mu1>5.0</mu1>
    <mu2>5.0</mu2>
    <material>Gazebo/Grey</material>
    <turnGravityOff>false</turnGravityOff>
  </gazebo>
  <gazebo reference="joint_2_l">
    <mu1>5.0</mu1>
    <mu2>5.0</mu2>
    <material>Gazebo/Grey</material>
    <turnGravityOff>false</turnGravityOff>
  </gazebo>
  <gazebo reference="joint_3_u">
    <mu1>5.0</mu1>
    <mu2>5.0</mu2>
    <material>Gazebo/Grey</material>
    <turnGravityOff>false</turnGravityOff>
  </gazebo>
  <gazebo reference="joint_4_r">
    <mu1>5.0</mu1>
    <mu2>5.0</mu2>
    <material>Gazebo/Grey</material>
    <turnGravityOff>false</turnGravityOff>
  </gazebo>
  <gazebo reference="joint_5_b">
    <mu1>5.0</mu1>
    <mu2>5.0</mu2>
    <material>Gazebo/Grey</material>
    <turnGravityOff>false</turnGravityOff>
  </gazebo>
  <gazebo reference="joint_6_t">
    <mu1>5.0</mu1>
    <mu2>5.0</mu2>
    <material>Gazebo/Grey</material>
    <turnGravityOff>false</turnGravityOff>
  </gazebo>
  <!--gazebo reference="finger1">
    <implicitSpringDamper>1</implicitSpringDamper>
    <kp>1000000.0</kp>
    <kd>1.0</kd>
    <mu1>10000.0</mu1>
    <mu2>10000.0</mu2>
    <minDepth>0.001</minDepth>
    <turnGravityOff>false</turnGravityOff>
</gazebo>

<gazebo reference="finger2">
    <implicitSpringDamper>1</implicitSpringDamper>
    <kp>1000000.0</kp>
    <kd>1.0</kd>
    <mu1>100000</mu1>
    <mu2>100000</mu2>
    <minDepth>0.001</minDepth>
    <turnGravityOff>false</turnGravityOff>
</gazebo-->
  <gazebo reference="camera_link">
    <sensor name="camera_1" type="depth">
      <always_on>true</always_on>
      <visualize>true</visualize>
      <update_rate>15.0</update_rate>
      <camera>
        <horizontal_fov>1.047197</horizontal_fov>
        <image>
          <format>B8G8R8</format>
          <width>640</width>
          <height>480</height>
        </image>
        <depth_camera>
        </depth_camera>
        <clip>
          <near>0.05</near>
          <far>50</far>
        </clip>
      </camera>
      <plugin filename="libgazebo_ros_openni_kinect.so" name="camera_controller">
        <baseline>0.1</baseline>
        <alwaysOn>true</alwaysOn>
        <updateRate>10.0</updateRate>
        <cameraName>kinect</cameraName>
        <frameName>camera_rgb_optical_frame</frameName>
        <imageTopicName>rgb/image_raw</imageTopicName>
        <depthImageTopicName>depth/image_raw</depthImageTopicName>
        <pointCloudTopicName>depth/points</pointCloudTopicName>
        <cameraInfoTopicName>rgb/camera_info</cameraInfoTopicName>
        <depthImageCameraInfoTopicName>depth/camera_info</depthImageCameraInfoTopicName>
        <pointCloudCutoff>0.4</pointCloudCutoff>
        <hackBaseline>0.07</hackBaseline>
        <distortionK1>0.0</distortionK1>
        <distortionK2>0.0</distortionK2>
        <distortionK3>0.0</distortionK3>
        <distortionT1>0.0</distortionT1>
        <distortionT2>0.0</distortionT2>
        <CxPrime>0.0</CxPrime>
        <Cx>0.0</Cx>
        <Cy>0.0</Cy>
        <focalLength>0.0</focalLength>
      </plugin>
    </sensor>
  </gazebo>
  <!--gazebo reference="realsense_link">
    <sensor type="depth" name="intelrealsense2">
      <always_on>1</always_on>
      <visualize>true</visualize>
      <camera>
        <horizontal_fov>1.047</horizontal_fov>
        <image>
          <width>640</width>
          <height>480</height>
          <format>R8G8B8</format>
        </image>
        <depth_camera>

        </depth_camera>
        <clip>
          <near>0.1</near>
          <far>100</far>
        </clip>
      </camera>
      <plugin name="intelrealsense" filename="libgazebo_ros_openni_kinect.so">
        <alwaysOn>true</alwaysOn>
        <updateRate>10.0</updateRate>
        <cameraName>realsense</cameraName>
        <frameName>realsense_depth_optical_frame</frameName>
        <imageTopicName>/realsense/color/image_raw</imageTopicName>
        <depthImageTopicName>/realsense/depth/image_raw</depthImageTopicName>
        <pointCloudTopicName>depth/points2</pointCloudTopicName>
        <cameraInfoTopicName>/realsense/color/camera_info</cameraInfoTopicName>
        <depthImageCameraInfoTopicName>/realsense/depth/camera_info</depthImageCameraInfoTopicName>
         <pointCloudCutoff>0.2</pointCloudCutoff>
         <pointCloudCutoffMax>10.0</pointCloudCutoffMax>
        <hackBaseline>0.07</hackBaseline>
        <distortionK1>0.0</distortionK1>
        <distortionK2>0.0</distortionK2>
        <distortionK3>0.0</distortionK3>
        <distortionT1>0.0</distortionT1>
        <distortionT2>0.0</distortionT2>
        <CxPrime>0.0</CxPrime>
        <Cx>0.0</Cx>
        <Cy>0.0</Cy>
        <focalLength>0.0</focalLength>
      </plugin>
    </sensor>
  </gazebo-->
  <!--gazebo>
   <plugin name="gazebo_grasp_fix" filename="libgazebo_grasp_fix.so">
        <arm>
           <arm_name>robot</arm_name>
           <palm_link>link5</palm_link>
           <gripper_link>finger1</gripper_link>
           <gripper_link>finger2</gripper_link>
        </arm>
       <forces_angle_tolerance>100</forces_angle_tolerance>
       <update_rate>1000</update_rate>
       <grip_count_threshold>1</grip_count_threshold>
       <max_grip_count>2</max_grip_count>
       <release_tolerance>0.005</release_tolerance>
       <disable_collisions_on_attach>true</disable_collisions_on_attach>
       <contact_topic>__default_topic__</contact_topic>
    </plugin>
</gazebo-->
  <!-- ...........................................control........................................................................... -->
  <gazebo>
    <plugin filename="libgazebo_ros_control.so" name="gazebo_ros_control">
      <robotNamespace>/</robotNamespace>
      <robotSimType>gazebo_ros_control/DefaultRobotHWSim</robotSimType>
      <legacyModeNS>true</legacyModeNS>
    </plugin>
  </gazebo>
  <transmission name="base_link1_control">
    <type>transmission_interface/SimpleTransmission</type>
    <joint name="joint_1_s">
      <hardwareInterface>hardware_interface/PositionJointInterface</hardwareInterface>
    </joint>
    <actuator name="base_link1_motor">
      <hardwareInterface>hardware_interface/PositionJointInterface</hardwareInterface>
      <mechanicalReduction>3</mechanicalReduction>
    </actuator>
  </transmission>
  <transmission name="link1_link2_control">
    <type>transmission_interface/SimpleTransmission</type>
    <joint name="joint_2_l">
      <hardwareInterface>hardware_interface/PositionJointInterface</hardwareInterface>
    </joint>
    <actuator name="link2_motor">
      <hardwareInterface>hardware_interface/PositionJointInterface</hardwareInterface>
      <mechanicalReduction>3</mechanicalReduction>
    </actuator>
  </transmission>
  <transmission name="link2_link3_control">
    <type>transmission_interface/SimpleTransmission</type>
    <joint name="joint_3_u">
      <hardwareInterface>hardware_interface/PositionJointInterface</hardwareInterface>
    </joint>
    <actuator name="link3_motor">
      <hardwareInterface>hardware_interface/PositionJointInterface</hardwareInterface>
      <mechanicalReduction>3</mechanicalReduction>
    </actuator>
  </transmission>
  <transmission name="link3_link4_control">
    <type>transmission_interface/SimpleTransmission</type>
    <joint name="joint_4_r">
      <hardwareInterface>hardware_interface/PositionJointInterface</hardwareInterface>
    </joint>
    <actuator name="link4_motor">
      <hardwareInterface>hardware_interface/PositionJointInterface</hardwareInterface>
      <mechanicalReduction>2</mechanicalReduction>
    </actuator>
  </transmission>
  <transmission name="link4_link5_control">
    <type>transmission_interface/SimpleTransmission</type>
    <joint name="joint_5_b">
      <hardwareInterface>hardware_interface/PositionJointInterface</hardwareInterface>
    </joint>
    <actuator name="link5_motor">
      <hardwareInterface>hardware_interface/PositionJointInterface</hardwareInterface>
      <mechanicalReduction>2</mechanicalReduction>
    </actuator>
  </transmission>
  <transmission name="link5_link6_control">
    <type>transmission_interface/SimpleTransmission</type>
    <joint name="joint_6_t">
      <hardwareInterface>hardware_interface/PositionJointInterface</hardwareInterface>
    </joint>
    <actuator name="link5_motor">
      <hardwareInterface>hardware_interface/PositionJointInterface</hardwareInterface>
      <mechanicalReduction>2</mechanicalReduction>
    </actuator>
  </transmission>
  <!--transmission name="link5_finger1_control">
    <type>transmission_interface/SimpleTransmission</type>
    <joint name="l_finger_joint">
     <hardwareInterface>hardware_interface/PositionJointInterface</hardwareInterface>
    </joint>
    <actuator name="l_finger_motor">
     <hardwareInterface>hardware_interface/PositionJointInterface</hardwareInterface>
     <mechanicalReduction>2</mechanicalReduction>
    </actuator>
</transmission>

<transmission name="link5_finger2_control">
    <type>transmission_interface/SimpleTransmission</type>
    <joint name="r_finger_joint">
     <hardwareInterface>hardware_interface/PositionJointInterface</hardwareInterface>
    </joint>
    <actuator name="r_finger_motor">
     <hardwareInterface>hardware_interface/PositionJointInterface</hardwareInterface>
     <mechanicalReduction>2</mechanicalReduction>
    </actuator>
</transmission-->
  <link name="gripper_base">
    <visual>
      <geometry>
        <mesh filename="package://motoman_motomini_support/meshes/gripper/base.stl"/>
      </geometry>
      <material name="white"/>
    </visual>
    <collision>
      <geometry>
        <mesh filename="package://motoman_motomini_support/meshes/gripper/base.stl"/>
      </geometry>
    </collision>
    <inertial>
      <origin rpy="0 0 0" xyz="0 0 0"/>
      <mass value="0.1"/>
      <inertia ixx="0.001" ixy="0.001" ixz="0.001" iyy="0.001" iyz="0.001" izz="0.001"/>
    </inertial>
  </link>
  <link name="claw_1a">
    <visual>
      <geometry>
        <mesh filename="package://motoman_motomini_support/meshes/gripper/claw_1.stl"/>
      </geometry>
      <material name="white"/>
    </visual>
    <collision>
      <geometry>
        <mesh filename="package://motoman_motomini_support/meshes/gripper/claw_1.stl"/>
      </geometry>
    </collision>
    <inertial>
      <origin rpy="0 0 0" xyz="0 0 0"/>
      <mass value="0.1"/>
      <inertia ixx="0.001" ixy="0.001" ixz="0.001" iyy="0.001" iyz="0.001" izz="0.001"/>
    </inertial>
  </link>
  <link name="claw_1b">
    <visual>
      <geometry>
        <mesh filename="package://motoman_motomini_support/meshes/gripper/claw_1.stl"/>
      </geometry>
      <material name="white"/>
    </visual>
    <collision>
      <geometry>
        <mesh filename="package://motoman_motomini_support/meshes/gripper/claw_1.stl"/>
      </geometry>
    </collision>
    <inertial>
      <origin rpy="0 0 0" xyz="0 0 0"/>
      <mass value="0.1"/>
      <inertia ixx="0.001" ixy="0.001" ixz="0.001" iyy="0.001" iyz="0.001" izz="0.001"/>
    </inertial>
  </link>
  <link name="claw_2a">
    <visual>
      <geometry>
        <mesh filename="package://motoman_motomini_support/meshes/gripper/claw_2.stl"/>
      </geometry>
      <material name="white"/>
    </visual>
    <collision>
      <geometry>
        <mesh filename="package://motoman_motomini_support/meshes/gripper/claw_2.stl"/>
      </geometry>
    </collision>
    <inertial>
      <origin rpy="0 0 0" xyz="0 0 0"/>
      <mass value="0.1"/>
      <inertia ixx="0.001" ixy="0.001" ixz="0.001" iyy="0.001" iyz="0.001" izz="0.001"/>
    </inertial>
  </link>
  <link name="claw_2b">
    <visual>
      <geometry>
        <mesh filename="package://motoman_motomini_support/meshes/gripper/claw_2.stl"/>
      </geometry>
      <material name="white"/>
    </visual>
    <collision>
      <geometry>
        <mesh filename="package://motoman_motomini_support/meshes/gripper/claw_2.stl"/>
      </geometry>
    </collision>
    <inertial>
      <origin rpy="0 0 0" xyz="0 0 0"/>
      <mass value="0.1"/>
      <inertia ixx="0.001" ixy="0.001" ixz="0.001" iyy="0.001" iyz="0.001" izz="0.001"/>
    </inertial>
  </link>
  <link name="link_1a">
    <visual>
      <geometry>
        <mesh filename="package://motoman_motomini_support/meshes/gripper/link_1.stl"/>
      </geometry>
      <material name="white"/>
    </visual>
    <collision>
      <geometry>
        <mesh filename="package://motoman_motomini_support/meshes/gripper/link_1.stl"/>
      </geometry>
    </collision>
    <inertial>
      <origin rpy="0 0 0" xyz="0 0 0"/>
      <mass value="0.1"/>
      <inertia ixx="0.001" ixy="0.001" ixz="0.001" iyy="0.001" iyz="0.001" izz="0.001"/>
    </inertial>
  </link>
  <link name="link_1b">
    <visual>
      <geometry>
        <mesh filename="package://motoman_motomini_support/meshes/gripper/link_1.stl"/>
      </geometry>
      <material name="white"/>
    </visual>
    <collision>
      <geometry>
        <mesh filename="package://motoman_motomini_support/meshes/gripper/link_1.stl"/>
      </geometry>
    </collision>
    <inertial>
      <origin rpy="0 0 0" xyz="0 0 0"/>
      <mass value="0.1"/>
      <inertia ixx="0.001" ixy="0.001" ixz="0.001" iyy="0.001" iyz="0.001" izz="0.001"/>
    </inertial>
  </link>
  <link name="link_2a">
    <visual>
      <geometry>
        <mesh filename="package://motoman_motomini_support/meshes/gripper/link_2.stl"/>
      </geometry>
      <material name="white"/>
    </visual>
    <collision>
      <geometry>
        <mesh filename="package://motoman_motomini_support/meshes/gripper/link_2.stl"/>
      </geometry>
    </collision>
    <inertial>
      <origin rpy="0 0 0" xyz="0 0 0"/>
      <mass value="0.1"/>
      <inertia ixx="0.001" ixy="0.001" ixz="0.001" iyy="0.001" iyz="0.001" izz="0.001"/>
    </inertial>
  </link>
  <link name="link_2b">
    <visual>
      <geometry>
        <mesh filename="package://motoman_motomini_support/meshes/gripper/link_2.stl"/>
      </geometry>
      <material name="white"/>
    </visual>
    <collision>
      <geometry>
        <mesh filename="package://motoman_motomini_support/meshes/gripper/link_2.stl"/>
      </geometry>
    </collision>
    <inertial>
      <origin rpy="0 0 0" xyz="0 0 0"/>
      <mass value="0.1"/>
      <inertia ixx="0.001" ixy="0.001" ixz="0.001" iyy="0.001" iyz="0.001" izz="0.001"/>
    </inertial>
  </link>
  <link name="link_2c">
    <visual>
      <geometry>
        <mesh filename="package://motoman_motomini_support/meshes/gripper/link_2.stl"/>
      </geometry>
      <material name="white"/>
    </visual>
    <collision>
      <geometry>
        <mesh filename="package://motoman_motomini_support/meshes/gripper/link_2.stl"/>
      </geometry>
    </collision>
    <inertial>
      <origin rpy="0 0 0" xyz="0 0 0"/>
      <mass value="0.1"/>
      <inertia ixx="0.001" ixy="0.001" ixz="0.001" iyy="0.001" iyz="0.001" izz="0.001"/>
    </inertial>
  </link>
  <link name="link_2d">
    <visual>
      <geometry>
        <mesh filename="package://motoman_motomini_support/meshes/gripper/link_2.stl"/>
      </geometry>
      <material name="white"/>
    </visual>
    <collision>
      <geometry>
        <mesh filename="package://motoman_motomini_support/meshes/gripper/link_2.stl"/>
      </geometry>
    </collision>
    <inertial>
      <origin rpy="0 0 0" xyz="0 0 0"/>
      <mass value="0.1"/>
      <inertia ixx="0.001" ixy="0.001" ixz="0.001" iyy="0.001" iyz="0.001" izz="0.001"/>
    </inertial>
  </link>
  <!--link name="servo_motor">
    <visual>
      <geometry>
        <box size="0.054 0.020 0.038"/>
      </geometry>
      <material name="white"/>
    </visual>
    <collision>
      <geometry>
        <box size="0.054 0.020 0.038"/>
      </geometry>
    </collision>
        <inertial>
        <origin xyz="0 0 0" rpy="0 0 0" />
        <mass value= "0.1"/>
        <inertia ixx="0.001" ixy="0.001" ixz="0.001" iyy="0.001" iyz="0.001" izz="0.001" />
    </inertial>
  </link-->
  <joint name="gripper_joint" type="fixed">
    <parent link="tool0"/>
    <child link="gripper_base"/>
    <origin rpy="0 -1.57079632679 3.14159265359" xyz="0 0 0"/>
    <!--<limit lower= "-3.0" upper= "3.0" effort="200" velocity="3" />
    <axis xyz = "0 0 1" />-->
  </joint>
  <joint name="claw_1b_joint" type="revolute">
    <parent link="gripper_base"/>
    <child link="claw_1b"/>
    <limit effort="200" lower="-3.0" upper="3.0" velocity="3"/>
    <axis xyz="0 0 1"/>
    <origin rpy="0.0 0.0 1.3386" xyz="0.045 0.01154 0.017503"/>
    <!-- 1.3386-->
  </joint>
  <joint name="claw_1a_joint" type="revolute">
    <parent link="gripper_base"/>
    <child link="claw_1a"/>
    <limit effort="200" lower="-3.0" upper="3.0" velocity="3"/>
    <axis xyz="0 0 1"/>
    <origin rpy="0.0 0.0 -1.3386" xyz="0.045 -0.01154 0.017503"/>
    <!-- -1.3386-->
    <mimic joint="claw_1b_joint" multiplier="-1"/>
  </joint>
  <joint name="claw_2a_joint" type="revolute">
    <parent link="claw_1a"/>
    <child link="claw_2a"/>
    <limit effort="200" lower="-3.0" upper="3.0" velocity="3"/>
    <axis xyz="0 0 1"/>
    <!--origin rpy="0.0 3.142 0" xyz="0.032 -0.011563 0.0050405"/-->
    <origin rpy="3.142 0 -1.6029994" xyz="0.03 0 -0.005"/>
    <mimic joint="claw_1b_joint" multiplier="-1"/>
  </joint>
  <joint name="claw_2b_joint" type="revolute">
    <parent link="claw_1b"/>
    <child link="claw_2b"/>
    <limit effort="200" lower="-3.0" upper="3.0" velocity="3"/>
    <axis xyz="0 0 1"/>
    <origin rpy="3.142 3.142 -1.6029994" xyz="0.03 0 -0.005"/>
    <mimic joint="claw_1b_joint" multiplier="-1"/>
  </joint>
  <joint name="link_1a_joint" type="revolute">
    <parent link="gripper_base"/>
    <child link="link_1a"/>
    <limit effort="200" lower="-3.0" upper="3.0" velocity="3"/>
    <axis xyz="0 0 1"/>
    <origin rpy="0.0 0.0 1.8033928" xyz="0.045 -0.01154 0.0044"/>
    <mimic joint="claw_1b_joint" multiplier="-1"/>
  </joint>
  <joint name="link_1b_joint" type="revolute">
    <parent link="gripper_base"/>
    <child link="link_1b"/>
    <limit effort="200" lower="-3.0" upper="3.0" velocity="3"/>
    <axis xyz="0 0 1"/>
    <origin rpy="0.0 0.0 -1.8033928" xyz="0.045 0.01154 0.0044"/>
    <mimic joint="claw_1b_joint" multiplier="1"/>
  </joint>
  <joint name="link_2a_joint" type="revolute">
    <parent link="gripper_base"/>
    <child link="link_2a"/>
    <limit effort="200" lower="-3.0" upper="3.0" velocity="3"/>
    <axis xyz="0 0 1"/>
    <origin rpy="0.0 0.0 1.8033928" xyz="0.062257 -0.0040985 0.02"/>
    <mimic joint="claw_1b_joint" multiplier="-1"/>
  </joint>
  <joint name="link_2b_joint" type="revolute">
    <parent link="gripper_base"/>
    <child link="link_2b"/>
    <limit effort="200" lower="-3.0" upper="3.0" velocity="3"/>
    <axis xyz="0 0 1"/>
    <origin rpy="0.0 0.0 -1.8033928" xyz="0.062257 0.0040985 0.02"/>
    <mimic joint="claw_1b_joint" multiplier="1"/>
  </joint>
  <joint name="link_2c_joint" type="revolute">
    <parent link="gripper_base"/>
    <child link="link_2c"/>
    <limit effort="200" lower="-3.0" upper="3.0" velocity="3"/>
    <axis xyz="0 0 1"/>
    <origin rpy="0.0 0.0 1.8033928" xyz="0.062257 -0.0040985 0.005"/>
    <mimic joint="claw_1b_joint" multiplier="-1"/>
  </joint>
  <joint name="link_2d_joint" type="revolute">
    <parent link="gripper_base"/>
    <child link="link_2d"/>
    <limit effort="200" lower="-3.0" upper="3.0" velocity="3"/>
    <axis xyz="0 0 1"/>
    <origin rpy="0.0 0.0 -1.8033928" xyz="0.062257 0.0040985 0.005"/>
    <mimic joint="claw_1b_joint" multiplier="1"/>
  </joint>
  <!--joint name="servo_joint" type="fixed">
    <parent link="gripper_base"/>
    <child link="servo_motor"/>
    <origin rpy="0.0 0.0 1.5707" xyz="0.062257 0.0040985 0"/>
  </joint-->
  <link name="realsense_link">
    <collision>
      <origin rpy="0 0 0" xyz="0.02 0 0"/>
      <geometry>
        <box size="0.001 0.001 0.001"/>
      </geometry>
    </collision>
    <visual>
      <origin rpy="1.5707 0 1.5707" xyz="0 0 0"/>
      <geometry>
        <mesh filename="package://motoman_motomini_support/meshes/NAVRS.STL"/>
      </geometry>
    </visual>
    <inertial>
      <mass value="1e-5"/>
      <origin rpy="0 0 0" xyz="0 0 0"/>
      <inertia ixx="0" ixy="0" ixz="0" iyy="0" iyz="0" izz="0"/>
    </inertial>
  </link>
  <joint name="realsense_joint" type="fixed">
    <parent link="gripper_base"/>
    <child link="realsense_link"/>
    <origin rpy="0 0 0" xyz="0.05 0 0.055"/>
    <!--<limit lower= "-3.0" upper= "3.0" effort="200" velocity="3" />
    <axis xyz = "0 0 1" />-->
  </joint>
  <joint name="camera_optical_joint2" type="fixed">
    <origin rpy="-1.57079632679 0 -1.57079632679" xyz="0 0 0"/>
    <parent link="realsense_link"/>
    <child link="realsense_rgb_optical_frame"/>
  </joint>
  <link name="realsense_rgb_optical_frame">
  </link>
  <joint name="camera_depth_joint2" type="fixed">
    <origin rpy="-1.57079632679 0 -1.57079632679" xyz="0 0 0"/>
    <parent link="realsense_link"/>
    <child link="realsense_depth_optical_frame"/>
  </joint>
  <link name="realsense_depth_optical_frame">
  </link>
</robot>
